Workbook

Sheet START HERE
A1: ServiceNow Architecture Discovery Workbook
A2: Purpose | B2: Learn an inherited ServiceNow instance by tracing real work, record what you can PROVE, and make unknowns and risks visible - with limited access. Companion to the Obsidian vault (same IDs, same vocabulary).
A4: PRINCIPLES
A5: ServiceNow is authoritative | B5: If this workbook disagrees with the platform, the platform wins until you resolve the difference. Update the workbook, set Last Reviewed.
A6: Never guess | B6: If you don't know why something exists, log it on the Unknowns sheet. Write 'UNKNOWN' in Purpose columns. Do not invent reasons.
A7: Document relationships | B7: A table name is less useful than knowing what depends on it. Use the Dependencies sheet and Impact Check.
A8: Business purpose first | B8: Link objects to a Business Process. If you cannot, say so.
A9: Track ownership and confidence | B9: Every Critical/High object should end with an owner. Every row has a Confidence level (High=verified, Medium=strongly supported, Low=inferred).
A10: Capture why | B10: Record decisions (and reconstructed decisions, labeled as such).
A11: Build incrementally | B11: Do not try to document the whole platform. Document what you encounter while tracing real processes.
A13: HOW TO USE (daily loop)
A14: 1. Architecture Overview | B14: Fill what you can verify. Everything else becomes an Unknown.
A15: 2. Inventory | B15: Add rows to Object Inventory (existence + owner + criticality) and Applications.
A16: 3. Pick processes | B16: Business Processes sheet: choose 3-5, set Priority to Trace.
A17: 4. Trace end-to-end | B17: User -> catalog -> variables -> flow -> tables -> scripts -> notifications -> approvals -> integrations -> reporting.
A18: 5. Document as you meet objects | B18: Use the detail sheet for the type (Tables, Flows, ...). Add an Object Inventory row for each.
A19: 6. Record relationships | B19: Dependencies sheet: Source -> relationship -> Target. Use exact object names.
A20: 7. Record Unknowns and Risks | B20: Never leave a question in your head. Set Access Needed - that builds your access case.
A21: 8. Validate with SMEs | B21: Set Confidence to High only when verified directly. Record who validated and when.
A22: 9. Check the Dashboard | B22: See coverage, owner gaps, critical risks. Update Current Focus.
A23: 10. Before any change | B23: Use Impact Check, then Decisions and Change History.
A25: SHEET MAP
A26: Dashboard | B26: Metrics (formulas)
A27: Architecture Overview | B27: Instance facts, people, layers
A28: Object Inventory | B28: Master list of everything important
A29: Applications / Tables / Fields | B29: Application and data model
A30: Catalog Items / Variables | B30: Service catalog
A31: Flows / Scripts & Rules | B31: Automation and code
A32: Integrations | B32: External connections
A33: Security | B33: Roles, groups, ACLs
A34: Business Processes | B34: The spine - start here for tracing
A35: Dependencies / Impact Check | B35: Relationships and 'what breaks if I change this?'
A36: Risks / Unknowns | B36: Risk register (auto score) and unknowns register
A37: Decisions / Change History | B37: The 'why' and what changed
... A41: Reference Lists | B41: Dropdown values and definitions
A43: LEGEND
A44: Yellow + italic rows | B44: FICTIONAL EXAMPLES (IDs start EX-). They show how to fill a row. Not your environment. Excluded from Dashboard.
A45: Yellow input cells | B45: Cells you edit on Dashboard / Impact Check.
A46: Grey/blue header | B46: Hover headers with a red triangle for tips.
A47: Rows 'Suspected' on Risks | B47: Hypotheses to check, not findings.
...

Sheet Dashboard
A1: ARCHITECTURE DASHBOARD - all values are formulas. Yellow cells are yours to edit. Example rows (IDs starting EX-) are excluded.
A3: FOCUS (edit)
A4: Current discovery focus | B4: (e.g., Process 1: ...)
A5: Next discovery target | B5: (e.g., ...)
A6: 30-day plan days done | B6: ='30-Day Plan'!M2 -> 0 / 30
A8: INVENTORY & COVERAGE
A9: Metric | B9: Discovered | C9: Documented | D9: % Documented
A10: Total objects (Object Inventory) | B10: =SUMPRODUCT(('Object Inventory'!$A$3:$A$502<>"")*(LEFT('Object Inventory'!$A$3:$A$502,3)<>"EX-")) -> 0 | C10: =SUMPRODUCT(('Object Inventory'!$A$3:$A$502<>"")*(LEFT('Object Inventory'!$A$3:$A$502,3)<>"EX-")*(('Object Inventory'!$O$3:$O$502="Documented")+('Object Inventory'!$O$3:$O$502="Validated"))) -> 0 | D10: =IF(B10=0,0,C10/B10) -> 0
A11: Tables | B11: =SUMPRODUCT((Tables!$A$3:$A$502<>"")*(LEFT(Tables!$A$3:$A$502,3)<>"EX-")) -> 0 | C11: =SUMPRODUCT((Tables!$A$3:$A$502<>"")*(LEFT(Tables!$A$3:$A$502,3)<>"EX-")*((Tables!$AY$3:$AY$502="Documented")+(Tables!$AY$3:$AY$502="Validated"))) -> 0 | D11: =IF(B11=0,0,C11/B11) -> 0
A12: Flows / Subflows | B12: =SUMPRODUCT((Flows!$A$3:$A$502<>"")*(LEFT(Flows!$A$3:$A$502,3)<>"EX-")) -> 0 | C12: =SUMPRODUCT((Flows!$A$3:$A$502<>"")*(LEFT(Flows!$A$3:$A$502,3)<>"EX-")*((Flows!$AI$3:$AI$502="Documented")+(Flows!$AI$3:$AI$502="Validated"))) -> 0 | D12: =IF(B12=0,0,C12/B12) -> 0
A13: Catalog items | B13: =SUMPRODUCT(('Catalog Items'!$A$3:$A$502<>"")*(LEFT('Catalog Items'!$A$3:$A$502,3)<>"EX-")) -> 0 | C13: =SUMPRODUCT(('Catalog Items'!$A$3:$A$502<>"")*(LEFT('Catalog Items'!$A$3:$A$502,3)<>"EX-")*(('Catalog Items'!$AB$3:$AB$502="Documented")+('Catalog Items'!$AB$3:$AB$502="Validated"))) -> 0 | D13: =IF(B13=0,0,C13/B13) -> 0
A14: Integrations | B14: =SUMPRODUCT((Integrations!$A$3:$A$502<>"")*(LEFT(Integrations!$A$3:$A$502,3)<>"EX-")) -> 0 | C14: =SUMPRODUCT((Integrations!$A$3:$A$502<>"")*(LEFT(Integrations!$A$3:$A$502,3)<>"EX-")*((Integrations!$AD$3:$AD$502="Documented")+(Integrations!$AD$3:$AD$502="Validated"))) -> 0 | D14: =IF(B14=0,0,C14/B14) -> 0
A15: Business processes | B15: =SUMPRODUCT(('Business Processes'!$A$3:$A$502<>"")*(LEFT('Business Processes'!$A$3:$A$502,3)<>"EX-")) -> 0 | C15: =SUMPRODUCT(('Business Processes'!$A$3:$A$502<>"")*(LEFT('Business Processes'!$A$3:$A$502,3)<>"EX-")*(('Business Processes'!$AC$3:$AC$502="Documented")+('Business Processes'!$AC$3:$AC$502="Validated"))) -> 0 | D15: =IF(B15=0,0,C15/B15) -> 0
A16: Scripts & rules | B16: =SUMPRODUCT(('Scripts & Rules'!$A$3:$A$502<>"")*(LEFT('Scripts & Rules'!$A$3:$A$502,3)<>"EX-")) -> 0 | C16: =SUMPRODUCT(('Scripts & Rules'!$A$3:$A$502<>"")*(LEFT('Scripts & Rules'!$A$3:$A$502,3)<>"EX-")*(('Scripts & Rules'!$AA$3:$AA$502="Documented")+('Scripts & Rules'!$AA$3:$AA$502="Validated"))) -> 0 | D16: =IF(B16=0,0,C16/B16) -> 0
A17: Security (roles/groups/ACLs) | B17: =SUMPRODUCT((Security!$A$3:$A$502<>"")*(LEFT(Security!$A$3:$A$502,3)<>"EX-")) -> 0 | C17: =SUMPRODUCT((Security!$A$3:$A$502<>"")*(LEFT(Security!$A$3:$A$502,3)<>"EX-")*((Security!$W$3:$W$502="Documented")+(Security!$W$3:$W$502="Validated"))) -> 0 | D17: =IF(B17=0,0,C17/B17) -> 0
A18: Applications | B18: =SUMPRODUCT((Applications!$A$3:$A$502<>"")*(LEFT(Applications!$A$3:$A$502,3)<>"EX-")) -> 0 | C18: =SUMPRODUCT((Applications!$A$3:$A$502<>"")*(LEFT(Applications!$A$3:$A$502,3)<>"EX-")*((Applications!$O$3:$O$502="Documented")+(Applications!$O$3:$O$502="Validated"))) -> 0 | D18: =IF(B18=0,0,C18/B18) -> 0
A19: Fields (tracked) | B19: =SUMPRODUCT((Fields!$A$3:$A$502<>"")*(LEFT(Fields!$A$3:$A$502,3)<>"EX-")) -> 0 | C19: =SUMPRODUCT((Fields!$A$3:$A$502<>"")*(LEFT(Fields!$A$3:$A$502,3)<>"EX-")*((Fields!$W$3:$W$502="Documented")+(Fields!$W$3:$W$502="Validated"))) -> 0 | D19: =IF(B19=0,0,C19/B19) -> 0
A20: Variables (tracked) | B20: =SUMPRODUCT((Variables!$A$3:$A$502<>"")*(LEFT(Variables!$A$3:$A$502,3)<>"EX-")) -> 0 | C20: =SUMPRODUCT((Variables!$A$3:$A$502<>"")*(LEFT(Variables!$A$3:$A$502,3)<>"EX-")*((Variables!$R$3:$R$502="Documented")+(Variables!$R$3:$R$502="Validated"))) -> 0 | D20: =IF(B20=0,0,C20/B20) -> 0
A21: OVERALL DOCUMENTATION % (Object Inventory) | D21: =D10 -> 0
A23: RISKS & UNKNOWNS (open items only)
A24: Critical risks | B24: =SUMPRODUCT((Risks!$A$3:$A$502<>"")*(LEFT(Risks!$A$3:$A$502,3)<>"EX-")*(Risks!$I$3:$I$502="Critical")*(Risks!$L$3:$L$502<>"Closed")*(Risks!$L$3:$L$502<>"Accepted")) -> 1
A25: High risks | B25: =SUMPRODUCT((Risks!$A$3:$A$502<>"")*(LEFT(Risks!$A$3:$A$502,3)<>"EX-")*(Risks!$I$3:$I$502="High")*(Risks!$L$3:$L$502<>"Closed")*(Risks!$L$3:$L$502<>"Accepted")) -> 1
A26: Suspected risks still to verify | B26: =SUMPRODUCT((Risks!$A$3:$A$502<>"")*(LEFT(Risks!$A$3:$A$502,3)<>"EX-")*(Risks!$L$3:$L$502="Suspected")) -> 16
A27: Critical unknowns (unresolved) | B27: =SUMPRODUCT((Unknowns!$A$3:$A$502<>"")*(LEFT(Unknowns!$A$3:$A$502,3)<>"EX-")*(Unknowns!$I$3:$I$502="Critical")*(Unknowns!$J$3:$J$502<>"Resolved")*(Unknowns!$J$3:$J$502<>"Closed - Not Resolvable")) -> 6
A28: High unknowns (unresolved) | B28: =SUMPRODUCT((Unknowns!$A$3:$A$502<>"")*(LEFT(Unknowns!$A$3:$A$502,3)<>"EX-")*(Unknowns!$I$3:$I$502="High")*(Unknowns!$J$3:$J$502<>"Resolved")*(Unknowns!$J$3:$J$502<>"Closed - Not Resolvable")) -> 5
A29: All unresolved unknowns | B29: =SUMPRODUCT((Unknowns!$A$3:$A$502<>"")*(LEFT(Unknowns!$A$3:$A$502,3)<>"EX-")*(Unknowns!$J$3:$J$502<>"Resolved")*(Unknowns!$J$3:$J$502<>"Closed - Not Resolvable")) -> 12
A30: Unknowns blocked by access | B30: =SUMPRODUCT((Unknowns!$A$3:$A$502<>"")*(LEFT(Unknowns!$A$3:$A$502,3)<>"EX-")*(Unknowns!$J$3:$J$502="Blocked - Needs Access")) -> 0 | F30: Use these to justify access requests
A32: OWNERSHIP & CUSTOMIZATION (Object Inventory)
A33: Undocumented customizations (Custom or Customized OOTB, not Documented/Validated) | B33: =SUMPRODUCT(('Object Inventory'!$A$3:$A$502<>"")*(LEFT('Object Inventory'!$A$3:$A$502,3)<>"EX-")*((('Object Inventory'!$M$3:$M$502="Custom")+('Object Inventory'!$M$3:$M$502="Customized OOTB"))>0)*(1-(('Object Inventory'!$O$3:$O$502="Documented")+('Object Inventory'!$O$3:$O$502="Validated")))) -> 0
A34: Objects with no owner (neither business nor technical) | B34: =SUMPRODUCT(('Object Inventory'!$A$3:$A$502<>"")*(LEFT('Object Inventory'!$A$3:$A$502,3)<>"EX-")*('Object Inventory'!$I$3:$I$502="")*('Object Inventory'!$J$3:$J$502="")) -> 0
A35: Objects with no technical owner | B35: =SUMPRODUCT(('Object Inventory'!$A$3:$A$502<>"")*(LEFT('Object Inventory'!$A$3:$A$502,3)<>"EX-")*('Object Inventory'!$J$3:$J$502="")) -> 0
A36: Low or Unknown confidence objects | B36: =SUMPRODUCT(('Object Inventory'!$A$3:$A$502<>"")*(LEFT('Object Inventory'!$A$3:$A$502,3)<>"EX-")*((('Object Inventory'!$P$3:$P$502="Low")+('Object Inventory'!$P$3:$P$502="Unknown")+('Object Inventory'!$P$3:$P$502=""))>0)) -> 0
A37: Critical objects not yet Documented/Validated | B37: =SUMPRODUCT(('Object Inventory'!$A$3:$A$502<>"")*(LEFT('Object Inventory'!$A$3:$A$502,3)<>"EX-")*('Object Inventory'!$N$3:$N$502="Critical")*(1-(('Object Inventory'!$O$3:$O$502="Documented")+('Object Inventory'!$O$3:$O$502="Validated")))) -> 0
A38: Dependency rows recorded | B38: =SUMPRODUCT((Dependencies!$A$3:$A$502<>"")*(LEFT(Dependencies!$A$3:$A$502,3)<>"EX-")) -> 0
A39: Example rows still present (all sheets) | B39: =SUMPRODUCT(--(LEFT('Object Inventory'!$A$3:$A$502,3)="EX-"))+SUMPRODUCT(--(LEFT(Tables!$A$3:$A$502,3)="EX-"))+SUMPRODUCT(--(LEFT(Flows!$A$3:$A$502,3)="EX-"))+SUMPRODUCT(--(LEFT('Catalog Items'!$A$3:$A$502,3)="EX-"))+SUMPRODUCT(--(LEFT(Integrations!$A$3:$A$502,3)="EX-"))+SUMPRODUCT(--(LEFT('Scripts & Rules'!$A$3:$A$502,3)="EX-"))+SUMPRODUCT(--(LEFT(Dependencies!$A$3:$A$502,3)="EX-"))+SUMPRODUCT(--(LEFT(Risks!$A$3:$A$502,3)="EX-"))+SUMPRODUCT(--(LEFT(Unknowns!$A$3:$A$502,3)="EX-")) -> 22 | F39: Fictional; delete when ready
A41: OBJECTS BY TYPE (Object Inventory)
A42: Object Type | B42: Discovered | C42: Documented | D42: % Documented | E42: No Owner
A43: Table | B43: =SUMPRODUCT(('Object Inventory'!$A$3:$A$502<>"")*(LEFT('Object Inventory'!$A$3:$A$502,3)<>"EX-")*('Object Inventory'!$D$3:$D$502=A43)) -> 0 | C43: =SUMPRODUCT(('Object Inventory'!$A$3:$A$502<>"")*(LEFT('Object Inventory'!$A$3:$A$502,3)<>"EX-")*('Object Inventory'!$D$3:$D$502=A43)*(('Object Inventory'!$O$3:$O$502="Documented")+('Object Inventory'!$O$3:$O$502="Validated"))) -> 0 | D43: =IF(B43=0,"",C43/B43) | E43: =SUMPRODUCT(('Object Inventory'!$A$3:$A$502<>"")*(LEFT('Object Inventory'!$A$3:$A$502,3)<>"EX-")*('Object Inventory'!$D$3:$D$502=A43)*('Object Inventory'!$I$3:$I$502="")*('Object Inventory'!$J$3:$J$502="")) -> 0
A44: Field | B44: =SUMPRODUCT(('Object Inventory'!$A$3:$A$502<>"")*(LEFT('Object Inventory'!$A$3:$A$502,3)<>"EX-")*('Object Inventory'!$D$3:$D$502=A44)) -> 0 | C44: =SUMPRODUCT(('Object Inventory'!$A$3:$A$502<>"")*(LEFT('Object Inventory'!$A$3:$A$502,3)<>"EX-")*('Object Inventory'!$D$3:$D$502=A44)*(('Object Inventory'!$O$3:$O$502="Documented")+('Object Inventory'!$O$3:$O$502="Validated"))) -> 0 | D44: =IF(B44=0,"",C44/B44) | E44: =SUMPRODUCT(('Object Inventory'!$A$3:$A$502<>"")*(LEFT('Object Inventory'!$A$3:$A$502,3)<>"EX-")*('Object Inventory'!$D$3:$D$502=A44)*('Object Inventory'!$I$3:$I$502="")*('Object Inventory'!$J$3:$J$502="")) -> 0
A45: Application | B45: =SUMPRODUCT(('Object Inventory'!$A$3:$A$502<>"")*(LEFT('Object Inventory'!$A$3:$A$502,3)<>"EX-")*('Object Inventory'!$D$3:$D$502=A45)) -> 0 | C45: =SUMPRODUCT(('Object Inventory'!$A$3:$A$502<>"")*(LEFT('Object Inventory'!$A$3:$A$502,3)<>"EX-")*('Object Inventory'!$D$3:$D$502=A45)*(('Object Inventory'!$O$3:$O$502="Documented")+('Object Inventory'!$O$3:$O$502="Validated"))) -> 0 | D45: =IF(B45=0,"",C45/B45) | E45: =SUMPRODUCT(('Object Inventory'!$A$3:$A$502<>"")*(LEFT('Object Inventory'!$A$3:$A$502,3)<>"EX-")*('Object Inventory'!$D$3:$D$502=A45)*('Object Inventory'!$I$3:$I$502="")*('Object Inventory'!$J$3:$J$502="")) -> 0
...

Sheet Architecture Overview
A1: ARCHITECTURE OVERVIEW - the front page of your instance. Fill what you can verify; leave the rest blank and log an Unknown. Do not guess.
A2: Item | B2: Value | C2: Evidence / Source | D2: Confidence | E2: Last Verified | F2: Notes / Linked Unknown ID
A3: INSTANCE
A4: Instance name | D4: Unknown
A5: Instance URL (production) | D5: Unknown
A6: Sub-production instance(s) and URLs | D6: Unknown
A7: Production / sub-production (this record is for) | D7: Unknown
A8: ServiceNow version / release | D8: Unknown
A9: Last upgrade (date) | D9: Unknown
A10: Next planned upgrade (date) | D10: Unknown
A11: Upgrade owner | D11: Unknown
A12: PEOPLE
A13: Platform owner | D13: Unknown
A14: Primary administrator | D14: Unknown
A15: Backup administrator | D15: Unknown
A16: Technical owner | D16: Unknown
A17: Business owner | D17: Unknown
A18: Vendor / partner support | D18: Unknown
A19: Now Support authorized contacts | D19: Unknown
A20: Security contact | D20: Unknown
A21: WHAT IS ON THE PLATFORM
A22: Major applications (see Applications sheet) | D22: Unknown
A23: Major modules | D23: Unknown
A24: Major business processes (see Business Processes sheet) | D24: Unknown
A25: Major external systems | D25: Unknown
A26: Major integrations (see Integrations sheet) | D26: Unknown
A27: Major customizations | D27: Unknown
A28: Critical platform dependencies (SSO, MID, email, external APIs) | D28: Unknown
A29: PROCESS & GOVERNANCE
A30: How changes move to production | D30: Unknown
A31: Change approval process | D31: Unknown
A32: Existing documentation location | D32: Unknown
A33: Testing approach (ATF / manual) | D33: Unknown
A34: Monitoring / alerting in place | D34: Unknown
A35: Architecture diagram location (Obsidian: 01 - PLATFORM/Diagram Library) | D35: Unknown
A37: ARCHITECTURE LAYERS (live counts from your sheets; examples excluded)
A38: Layer | B38: Where documented | C38: Rows recorded | D38: Documented / Validated
A39: Applications | B39: Applications | C39: =SUMPRODUCT((Applications!$A$3:$A$502<>"")*(LEFT(Applications!$A$3:$A$502,3)<>"EX-")) -> 0 | D39: =SUMPRODUCT((Applications!$A$3:$A$502<>"")*(LEFT(Applications!$A$3:$A$502,3)<>"EX-")*((Applications!$O$3:$O$502="Documented")+(Applications!$O$3:$O$502="Validated"))) -> 0
A40: Data Model (Tables) | B40: Tables | C40: =SUMPRODUCT((Tables!$A$3:$A$502<>"")*(LEFT(Tables!$A$3:$A$502,3)<>"EX-")) -> 0 | D40: =SUMPRODUCT((Tables!$A$3:$A$502<>"")*(LEFT(Tables!$A$3:$A$502,3)<>"EX-")*((Tables!$AY$3:$AY$502="Documented")+(Tables!$AY$3:$AY$502="Validated"))) -> 0
A41: Service Catalog | B41: Catalog Items | C41: =SUMPRODUCT(('Catalog Items'!$A$3:$A$502<>"")*(LEFT('Catalog Items'!$A$3:$A$502,3)<>"EX-")) -> 0 | D41: =SUMPRODUCT(('Catalog Items'!$A$3:$A$502<>"")*(LEFT('Catalog Items'!$A$3:$A$502,3)<>"EX-")*(('Catalog Items'!$AB$3:$AB$502="Documented")+('Catalog Items'!$AB$3:$AB$502="Validated"))) -> 0
...

Sheet Object Inventory
A1: MASTER OBJECT INVENTORY - one row per important object. Row = 'it exists'. Detail sheets/notes = 'how it works'. Examples are yellow/italic (IDs start EX-) and are excluded from Dashboard counts.
A2: Object ID | B2: Object Name | C2: Display Name | D2: Object Type | E2: Application | F2: Scope | G2: Purpose | H2: Business Process | I2: Business Owner | J2: Technical Owner | K2: Status | L2: Active/Inactive | M2: OOTB/Custom | N2: Criticality | O2: Documentation Status | P2: Confidence | Q2: Dependencies | R2: Dependents | S2: Related Objects | T2: Last Reviewed | U2: Access Needed | V2: sys_id / Link | W2: Detail Lives In | X2: Notes
A3: EX-OBJ-001 | B3: u_ex_asset_request | C3: Asset Request | D3: Table | E3: EXAMPLE Asset Requests | F3: x_ex_assetreq | G3: Stores each laptop/asset request | H3: EXAMPLE Laptop Request | K3: In Use | L3: Active | M3: Custom | N3: Critical | O3: Documented | P3: High | Q3: EX Laptop Request Fulfillment (updates) | R3: EX Set Cost Center Default; EX ACL write | U3: Elevated Application | W3: Tables | X3: EXAMPLE - FICTIONAL. Not part of your environment. Delete when you no longer need it.
A4: EX-OBJ-002 | B4: EX Laptop Request | C4: Laptop Request | D4: Catalog Item | E4: EXAMPLE Asset Requests | F4: x_ex_assetreq | G4: Employee-facing request form | H4: EXAMPLE Laptop Request | K4: In Use | L4: Active | M4: Custom | N4: High | O4: Documented | P4: High | Q4: EX Laptop Request Fulfillment | R4: Employees (portal) | U4: Basic User | W4: Catalog Items | X4: EXAMPLE - FICTIONAL. Not part of your environment. Delete when you no longer need it.
A5: EX-OBJ-003 | B5: EX Laptop Request Fulfillment | C5: Laptop Request Fulfillment | D5: Flow | E5: EXAMPLE Asset Requests | F5: x_ex_assetreq | G5: Approval, task creation, record updates | H5: EXAMPLE Laptop Request | K5: In Use | L5: Active | M5: Custom | N5: Critical | O5: Partially Documented | P5: Medium | Q5: EX Get Manager Approval; u_ex_asset_request; EX HR Employee Lookup | R5: EX Laptop Request | U5: Admin | W5: Flows | X5: EXAMPLE - FICTIONAL. Not part of your environment. Delete when you no longer need it.
A6: EX-OBJ-004 | B6: EX Set Cost Center Default | C6: Set Cost Center Default | D6: Business Rule | E6: EXAMPLE Asset Requests | F6: x_ex_assetreq | G6: UNKNOWN - see EX-U-001 | H6: EXAMPLE Laptop Request | K6: In Use | L6: Active | M6: Custom | N6: Medium | O6: Discovered | P6: Low | Q6: EXCostCenterUtil | R6: u_ex_asset_request inserts | U6: Admin | W6: Scripts & Rules | X6: EXAMPLE - FICTIONAL. Not part of your environment. Delete when you no longer need it.
A7: EX-OBJ-005 | B7: EX HR Employee Lookup | C7: HR Employee Lookup | D7: Integration | E7: EXAMPLE Integrations | F7: global | G7: Looks up employee data in a (fictional) HR system | H7: EXAMPLE Laptop Request | K7: In Use | L7: Active | M7: Custom | N7: High | O7: Partially Documented | P7: Low | Q7: External HR system | R7: EX Laptop Request Fulfillment | U7: Admin | W7: Integrations | X7: EXAMPLE - FICTIONAL. Not part of your environment. Delete when you no longer need it.
A8: EX-OBJ-006 | B8: x_ex_assetreq.fulfiller | C8: Asset Fulfiller | D8: Role | E8: EXAMPLE Asset Requests | F8: x_ex_assetreq | G8: Lets fulfillers work asset requests | K8: In Use | L8: Active | M8: Custom | N8: Medium | O8: Documented | P8: Medium | R8: EX ACL write u_ex_asset_request | U8: Admin | W8: Security | X8: EXAMPLE - FICTIONAL. Not part of your environment. Delete when you no longer need it.

Sheet Applications
A1: APPLICATIONS & MODULES - what is installed/used and why. Start here for Days 4-5 of the plan.
A2: App ID | B2: Application Name | C2: Scope | D2: Source (OOTB / Store / Custom) | E2: Version | F2: Active | G2: Purpose | H2: Business Owner | I2: Technical Owner | J2: Key Modules | K2: Key Tables | L2: Key Business Processes | M2: Primary Users / Groups | N2: Criticality | O2: Documentation Status | P2: Confidence | Q2: Evidence / Source | R2: Access Needed | S2: Last Reviewed | T2: Notes
A3: EX-APP-001 | B3: EXAMPLE Asset Requests | C3: x_ex_assetreq | D3: Custom | E3: 1.2 | F3: Active | G3: Employee asset requests | J3: Request Asset; Fulfill Asset | K3: u_ex_asset_request | L3: EXAMPLE Laptop Request | M3: All employees; EX Asset Fulfillment | N3: High | O3: Partially Documented | P3: Medium | R3: Basic User | T3: EXAMPLE - FICTIONAL. Not part of your environment. Delete when you no longer need it.

Sheet Tables
A1: TABLES / DATA MODEL - one row per table. Tip: for each table, ask 'who writes it, who reads it, what fires when a row changes, who can see it?'
A2: Table ID | B2: Table Name | C2: Label | D2: Application | E2: Scope | F2: Extends (Parent Table) | G2: Child Tables | H2: Purpose | I2: Business Process | J2: Business Owner | K2: Technical Owner | L2: Primary Key | M2: Display Field | N2: Record Volume | O2: Retention / Archive | P2: Important Fields | Q2: Sensitive Data | R2: Data Source | S2: Tables This References | T2: Tables Referencing This | U2: Many-to-Many Relationships | V2: Dependency Notes | W2: Business Rules | X2: Flows | Y2: Client Scripts | Z2: UI Policies | AA2: Script Includes | AB2: Scheduled Processes | AC2: Other Automation | AD2: Read ACLs | AE2: Create ACLs | AF2: Write ACLs | AG2: Delete ACLs | AH2: Roles | AI2: Groups | AJ2: Sensitive-Data Restrictions | AK2: Written To By (systems) | AL2: Read By (systems) | AM2: APIs | AN2: Import Sets | AO2: Transform Maps | AP2: MID Server Dependencies | AQ2: OOTB/Custom | AR2: Customized OOTB Objects | AS2: Reason for Customization | AT2: Upgrade Implications | AU2: Technical Debt | AV2: Criticality | AW2: Unknowns (link IDs) | AX2: Open Questions | AY2: Documentation Status | AZ2: Confidence | BA2: Evidence / Source | BB2: Access Needed | BC2: Last Reviewed | BD2: Notes
A3: EX-TBL-001 | B3: u_ex_asset_request | C3: Asset Request | D3: EXAMPLE Asset Requests | E3: x_ex_assetreq | F3: task | H3: One row per asset request | I3: EXAMPLE Laptop Request | L3: sys_id | M3: number | N3: ~400/month (fictional) | P3: u_cost_center; u_asset_type; state | Q3: None identified | R3: Catalog + flow | S3: sys_user; cmn_cost_center | W3: EX Set Cost Center Default | X3: EX Laptop Request Fulfillment | AF3: EX ACL write u_ex_asset_request | AH3: x_ex_assetreq.fulfiller | AQ3: Custom | AV3: Critical | AW3: EX-U-001 | AY3: Documented | AZ3: High | BA3: Fictional | BB3: Admin | BD3: EXAMPLE - FICTIONAL. Not part of your environment. Delete when you no longer need it.

Sheet Fields
A1: FIELDS - document only fields that matter: referenced by automation, ACLs, reports, integrations, or that you had to ask about. Column T is the point: what happens downstream when this value changes?
A2: Field ID | B2: Table | C2: Field Name (element) | D2: Label | E2: Type | F2: Length | G2: Reference Table | H2: Reference Qualifier | I2: Default Value | J2: Mandatory | K2: Read-only | L2: Choice Field | M2: Choices | N2: Calculated | O2: Attributes | P2: Dictionary Overrides | Q2: Business Purpose | R2: Read By (rules/flows/reports) | S2: Written By (rules/flows/integrations) | T2: Downstream Behavior (what changes when the value changes) | U2: Dependencies | V2: Criticality | W2: Documentation Status | X2: Confidence | Y2: Evidence / Source | Z2: Access Needed | AA2: Last Reviewed | AB2: Notes
A3: EX-FLD-001 | B3: u_ex_asset_request | C3: u_cost_center | D3: Cost Center | E3: Reference | G3: cmn_cost_center | H3: active=true | J3: Yes | Q3: Charges the asset to a department | R3: Fulfillment flow; Finance report | S3: EX Set Cost Center Default; requester | T3: Selects approver group in flow; changes Finance report grouping | V3: High | W3: Documented | X3: Medium | Z3: Admin | AB3: EXAMPLE - FICTIONAL. Not part of your environment. Delete when you no longer need it.

Sheet Catalog Items
A1: SERVICE CATALOG ITEMS - trace one item end-to-end: what the requester sees -> what records/approvals/tasks/notifications it creates.
A2: Catalog Item ID | B2: Catalog | C2: Category | D2: Name | E2: Technical Name | F2: Business Owner | G2: Technical Owner | H2: Purpose | I2: Business Process | J2: Active | K2: Criticality | L2: Available To (user criteria / roles) | M2: Variables | N2: Variable Sets | O2: UI Policies | P2: Catalog Client Scripts | Q2: Reference Qualifiers | R2: Flow | S2: Subflows | T2: Approvals | U2: Tasks | V2: Notifications | W2: Tables Touched | X2: Integrations | Y2: Users / Groups (requesters, fulfillers) | Z2: Dependencies | AA2: Known Issues | AB2: Documentation Status | AC2: Confidence | AD2: Evidence / Source | AE2: Access Needed | AF2: Last Reviewed | AG2: Notes
A3: EX-CI-001 | B3: Employee Services | C3: Hardware | D3: EXAMPLE Laptop Request | E3: ex_laptop_request | H3: Request a laptop | I3: EXAMPLE Laptop Request | J3: Active | K3: High | L3: All employees | M3: laptop_model; cost_center; justification | R3: EX Laptop Request Fulfillment | S3: EX Get Manager Approval | T3: Manager | U3: Fulfillment task -> EX Asset Fulfillment | V3: Approval request; Shipped | W3: sc_request; sc_req_item; u_ex_asset_request | X3: EX HR Employee Lookup | AB3: Partially Documented | AC3: Medium | AE3: Basic User | AG3: EXAMPLE - FICTIONAL. Not part of your environment. Delete when you no longer need it.

Sheet Variables
A1: VARIABLES - one row per variable that drives behavior (approvals, routing, integrations). Skip purely cosmetic ones.
A2: Variable ID | B2: Variable Name | C2: Label | D2: Type | E2: Catalog Item | F2: Variable Set | G2: Reference Table | H2: Reference Qualifier | I2: Default | J2: Mandatory | K2: Read-only | L2: Visibility Conditions | M2: Catalog Client Scripts | N2: UI Policies | O2: Feeds Into (flow/script/task field that reads it) | P2: Dependencies | Q2: Criticality | R2: Documentation Status | S2: Confidence | T2: Evidence / Source | U2: Access Needed | V2: Last Reviewed | W2: Notes
A3: EX-VAR-001 | B3: laptop_model | C3: Laptop Model | D3: Select Box | E3: EXAMPLE Laptop Request | J3: Yes | O3: Flow branches on model to pick approver; sets u_asset_type | Q3: High | R3: Documented | S3: Medium | U3: Basic User | W3: EXAMPLE - FICTIONAL. Not part of your environment. Delete when you no longer need it.

Sheet Flows
A1: FLOWS / AUTOMATION - the 2 questions: (1) if this flow stops, what breaks? (col AE) (2) if I change table/field X, which flows are affected? (filter 'Tables Read/Updated').
A2: Flow ID | B2: Flow Name | C2: Technical Name | D2: Component Type | E2: Application | F2: Scope | G2: Active | H2: Business Owner | I2: Technical Owner | J2: Purpose | K2: Business Process | L2: Trigger | M2: Trigger Conditions | N2: Inputs | O2: Outputs | P2: Tables Read | Q2: Tables Created | R2: Tables Updated | S2: Subflows Called | T2: Actions Used | U2: Script Actions | V2: Integrations | W2: Notifications | X2: Approvals | Y2: Error Handling | Z2: Failure Behavior | AA2: Logging | AB2: Retry Behavior | AC2: Dependencies | AD2: Dependents | AE2: If This Stops, What Business Process Breaks? | AF2: Criticality | AG2: Known Issues | AH2: Technical Debt | AI2: Documentation Status | AJ2: Confidence | AK2: Evidence / Source | AL2: Access Needed | AM2: Last Reviewed | AN2: Notes
A3: EX-FLOW-001 | B3: EX Laptop Request Fulfillment | C3: x_ex_assetreq.laptop_fulfillment | D3: Flow | E3: EXAMPLE Asset Requests | F3: x_ex_assetreq | G3: Active | J3: Orchestrates approval, task, and record updates | K3: EXAMPLE Laptop Request | L3: Service Catalog (request item created) | M3: Catalog item = EX Laptop Request | P3: sc_req_item; sys_user | Q3: u_ex_asset_request; sc_task | R3: u_ex_asset_request; sc_req_item | S3: EX Get Manager Approval | V3: EX HR Employee Lookup | X3: Manager | Y3: None observed (example) | Z3: UNKNOWN | AA3: Flow execution only | AB3: None | AE3: No laptop requests get approved or fulfilled; requests sit in 'Open' | AF3: Critical | AG3: No alerting on failed executions (example) | AI3: Partially Documented | AJ3: Medium | AL3: Admin | AN3: EXAMPLE - FICTIONAL. Not part of your environment. Delete when you no longer need it.

Sheet Scripts & Rules
A1: SCRIPTS & RULES - Business Rules, Client Scripts, Script Includes, UI Actions, etc. Hunt for hidden dependencies: hard-coded sys_ids, group/user names, other tables written, calls to other scripts (col S).
A2: Script ID | B2: Name | C2: Script Type | D2: Technical Name | E2: Application | F2: Scope | G2: Table | H2: Active | I2: Trigger / When It Runs | J2: Order | K2: Conditions | L2: Purpose (verified, or write UNKNOWN) | M2: Reads | N2: Writes | O2: Functions / Script Includes Called | P2: Called By | Q2: Tables Affected | R2: Other Dependencies | S2: Hard-coded Values (sys_ids, names, emails, URLs) | T2: Potential Side Effects | U2: Performance Concerns | V2: Security Concerns | W2: Criticality | X2: OOTB/Custom | Y2: Known Issues | Z2: Technical Debt | AA2: Documentation Status | AB2: Confidence | AC2: Evidence / Source | AD2: Access Needed | AE2: Last Reviewed | AF2: Notes
A3: EX-SCR-001 | B3: EX Set Cost Center Default | C3: Business Rule | E3: EXAMPLE Asset Requests | F3: x_ex_assetreq | G3: u_ex_asset_request | H3: Active | I3: Before insert | J3: 100 | K3: cost center is empty | L3: UNKNOWN - appears to default cost center; reason not verified | M3: sys_user.department | N3: u_ex_asset_request.u_cost_center | O3: EXCostCenterUtil.getDefault() | Q3: u_ex_asset_request | S3: One hard-coded group sys_id in line 14 (example) | T3: Overrides requester choice if department blank | W3: Medium | X3: Custom | Z3: Hard-coded sys_id | AA3: Discovered | AB3: Low | AD3: Admin | AF3: EXAMPLE - FICTIONAL. Not part of your environment. Delete when you no longer need it.

Sheet Integrations
A1: INTEGRATIONS - every connection in or out. An integration with no known owner, credential expiry or alerting is a risk row waiting to be written.
A2: Integration ID | B2: Integration Name | C2: External System | D2: Direction | E2: Purpose | F2: Technology | G2: API / Service Used | H2: Endpoint / Connection | I2: Authentication | J2: Integration User | K2: Credential Owner / Expiry | L2: MID Server | M2: Data Source | N2: Import Set | O2: Transform Map | P2: Target Table | Q2: Schedule | R2: Trigger | S2: Data Exchanged | T2: Failure Logging | U2: Alerting | V2: Retry / Recovery | W2: Dependencies | X2: Business Owner | Y2: Technical Owner | Z2: External Contact | AA2: Active | AB2: Criticality | AC2: Known Issues | AD2: Documentation Status | AE2: Confidence | AF2: Evidence / Source | AG2: Access Needed | AH2: Last Reviewed | AI2: Notes
A3: EX-INT-001 | B3: EX HR Employee Lookup | C3: EXAMPLE HR System (fictional) | D3: Outbound | E3: Fetch employee manager/cost center | F3: REST | H3: https://hr.example.invalid/api (fictional) | I3: OAuth 2.0 | J3: UNKNOWN | K3: UNKNOWN | R3: Called from fulfillment flow | S3: employee id -> manager, cost center | T3: Unknown | U3: None known | AA3: Active | AB3: High | AD3: Partially Documented | AE3: Low | AG3: Admin | AI3: EXAMPLE - FICTIONAL. Not part of your environment. Delete when you no longer need it.

Sheet Security
A1: SECURITY - roles, groups and ACLs in one table (filter by Record Type). Answers: who can SEE it, CHANGE it, EXECUTE it, and what happens if a role/group/ACL changes?
A2: Security ID | B2: Record Type | C2: Name (role / group / ACL name) | D2: Purpose | E2: Table (ACL) | F2: Field (ACL) | G2: Operation (ACL) | H2: ACL Condition | I2: ACL Script | J2: Required Roles / Parent Roles / Group Roles | K2: Assigned Users / Members (counts or names) | L2: Assigned Groups | M2: Apps / Modules Affected | N2: Privileges / Effect (who can see/change/execute) | O2: Manager / Owner | P2: Business Function | Q2: Responsibilities | R2: Dependencies | S2: What Happens If This Changes? | T2: Security Risk | U2: Active | V2: Criticality | W2: Documentation Status | X2: Confidence | Y2: Evidence / Source | Z2: Access Needed | AA2: Last Reviewed | AB2: Notes
A3: EX-SEC-001 | B3: Role | C3: x_ex_assetreq.fulfiller | D3: Work asset requests | J3: Contains: (none) | L3: EX Asset Fulfillment | M3: EXAMPLE Asset Requests | N3: Read/write u_ex_asset_request | S3: Fulfillers lose access to request records | V3: Medium | W3: Documented | X3: Medium | Z3: Admin | AB3: EXAMPLE - FICTIONAL. Not part of your environment. Delete when you no longer need it.
A4: EX-SEC-002 | B4: ACL | C4: EX ACL write u_ex_asset_request | E4: u_ex_asset_request | F4: * | G4: write | J4: x_ex_assetreq.fulfiller | N4: Only fulfillers can edit | S4: Widening it lets requesters edit approved requests | V4: High | W4: Documented | X4: Medium | Z4: Admin | AB4: EXAMPLE - FICTIONAL. Not part of your environment. Delete when you no longer need it.

Sheet Business Processes
A1: BUSINESS PROCESSES - the spine of this system. Pick 3-5, trace each end-to-end, then link every object you meet back to its process.
A2: Process ID | B2: Process Name | C2: Business Purpose | D2: Process Owner | E2: Trigger | F2: Users Involved | G2: Process Steps (numbered) | H2: ServiceNow Application(s) | I2: Tables | J2: Key Fields | K2: Catalog Items | L2: Flows | M2: Scripts | N2: Notifications | O2: Approvals | P2: Integrations | Q2: Reports | R2: Roles / Groups | S2: Manual Steps | T2: Failure Points | U2: Workarounds | V2: Known Pain Points | W2: Business Impact If It Fails | X2: Volume / Frequency | Y2: Criticality | Z2: Priority to Trace | AA2: SME Validated By | AB2: SME Validated Date | AC2: Documentation Status | AD2: Confidence | AE2: Evidence / Source | AF2: Access Needed | AG2: Last Reviewed | AH2: Notes
A3: EX-BP-001 | B3: EXAMPLE Laptop Request | C3: Employees get approved equipment quickly | D3: (example) IT Operations Manager | E3: Employee submits catalog item | F3: Employee; Manager; Fulfiller | G3: 1 Employee submits. 2 Manager approves. 3 Fulfillment task created. 4 Fulfiller ships. 5 Asset record updated. | H3: EXAMPLE Asset Requests | I3: sc_req_item; u_ex_asset_request | K3: EX Laptop Request | L3: EX Laptop Request Fulfillment | M3: EX Set Cost Center Default | O3: Manager | P3: EX HR Employee Lookup | S3: Shipping handled outside ServiceNow | T3: HR lookup fails -> flow stalls (no alert) | W3: New hires without equipment | Y3: High | Z3: High | AC3: Partially Documented | AD3: Medium | AF3: Basic User | AH3: EXAMPLE - FICTIONAL. Not part of your environment. Delete when you no longer need it.

Sheet Dependencies
A1: DEPENDENCIES - one row = 'Source --relationship--> Target'. Use the SAME names as Object Inventory so Impact Check can find them. Add the reverse reading for free: anything pointing AT an object is a dependent.
A2: Dependency ID | B2: Source Object ID | C2: Source Type | D2: Source Name | E2: Relationship | F2: Target Object ID | G2: Target Type | H2: Target Name | I2: Dependency Type | J2: Criticality | K2: Evidence | L2: Confidence | M2: Date Recorded | N2: Last Verified | O2: Notes | P2: Helper: Inbound # (do not edit) | Q2: Helper: Outbound # (do not edit)
A3: EX-DEP-001 | C3: Catalog Item | D3: EX Laptop Request | E3: launches | G3: Flow | H3: EX Laptop Request Fulfillment | I3: Automation | J3: High | K3: Fictional | L3: Medium | O3: EXAMPLE - FICTIONAL. Not part of your environment. Delete when you no longer need it. | P3: =IF(H3="","",IF(H3='Impact Check'!$B$3,COUNTIF($H$3:H3,'Impact Check'!$B$3),"")) | Q3: =IF(D3="","",IF(D3='Impact Check'!$B$3,COUNTIF($D$3:D3,'Impact Check'!$B$3),""))
A4: EX-DEP-002 | C4: Flow | D4: EX Laptop Request Fulfillment | E4: calls | G4: Subflow | H4: EX Get Manager Approval | I4: Automation | J4: High | K4: Fictional | L4: Medium | O4: EXAMPLE - FICTIONAL. Not part of your environment. Delete when you no longer need it. | P4: =IF(H4="","",IF(H4='Impact Check'!$B$3,COUNTIF($H$3:H4,'Impact Check'!$B$3),"")) | Q4: =IF(D4="","",IF(D4='Impact Check'!$B$3,COUNTIF($D$3:D4,'Impact Check'!$B$3),""))
A5: EX-DEP-003 | C5: Flow | D5: EX Laptop Request Fulfillment | E5: updates | G5: Table | H5: u_ex_asset_request | I5: Data | J5: Critical | K5: Fictional | L5: Medium | O5: EXAMPLE - FICTIONAL. Not part of your environment. Delete when you no longer need it. | P5: =IF(H5="","",IF(H5='Impact Check'!$B$3,COUNTIF($H$3:H5,'Impact Check'!$B$3),"")) -> 1 | Q5: =IF(D5="","",IF(D5='Impact Check'!$B$3,COUNTIF($D$3:D5,'Impact Check'!$B$3),""))
A6: EX-DEP-004 | C6: Flow | D6: EX Laptop Request Fulfillment | E6: calls | G6: Integration | H6: EX HR Employee Lookup | I6: Integration | J6: High | K6: Fictional | L6: Low | O6: EXAMPLE - FICTIONAL. Not part of your environment. Delete when you no longer need it. | P6: =IF(H6="","",IF(H6='Impact Check'!$B$3,COUNTIF($H$3:H6,'Impact Check'!$B$3),"")) | Q6: =IF(D6="","",IF(D6='Impact Check'!$B$3,COUNTIF($D$3:D6,'Impact Check'!$B$3),""))
A7: EX-DEP-005 | C7: Business Rule | D7: EX Set Cost Center Default | E7: runs on | G7: Table | H7: u_ex_asset_request | I7: Code | J7: Medium | K7: Fictional | L7: Medium | O7: EXAMPLE - FICTIONAL. Not part of your environment. Delete when you no longer need it. | P7: =IF(H7="","",IF(H7='Impact Check'!$B$3,COUNTIF($H$3:H7,'Impact Check'!$B$3),"")) -> 2 | Q7: =IF(D7="","",IF(D7='Impact Check'!$B$3,COUNTIF($D$3:D7,'Impact Check'!$B$3),""))
A8: EX-DEP-006 | C8: Business Rule | D8: EX Set Cost Center Default | E8: calls | G8: Script Include | H8: EXCostCenterUtil | I8: Code | J8: Medium | K8: Fictional | L8: Medium | O8: EXAMPLE - FICTIONAL. Not part of your environment. Delete when you no longer need it. | P8: =IF(H8="","",IF(H8='Impact Check'!$B$3,COUNTIF($H$3:H8,'Impact Check'!$B$3),"")) | Q8: =IF(D8="","",IF(D8='Impact Check'!$B$3,COUNTIF($D$3:D8,'Impact Check'!$B$3),""))
A9: EX-DEP-007 | C9: ACL | D9: EX ACL write u_ex_asset_request | E9: protects | G9: Table | H9: u_ex_asset_request | I9: Security | J9: High | K9: Fictional | L9: Medium | O9: EXAMPLE - FICTIONAL. Not part of your environment. Delete when you no longer need it. | P9: =IF(H9="","",IF(H9='Impact Check'!$B$3,COUNTIF($H$3:H9,'Impact Check'!$B$3),"")) -> 3 | Q9: =IF(D9="","",IF(D9='Impact Check'!$B$3,COUNTIF($D$3:D9,'Impact Check'!$B$3),""))
A10: EX-DEP-008 | C10: ACL | D10: EX ACL write u_ex_asset_request | E10: requires role | G10: Role | H10: x_ex_assetreq.fulfiller | I10: Security | J10: High | K10: Fictional | L10: Medium | O10: EXAMPLE - FICTIONAL. Not part of your environment. Delete when you no longer need it. | P10: =IF(H10="","",IF(H10='Impact Check'!$B$3,COUNTIF($H$3:H10,'Impact Check'!$B$3),"")) | Q10: =IF(D10="","",IF(D10='Impact Check'!$B$3,COUNTIF($D$3:D10,'Impact Check'!$B$3),""))
A11: EX-DEP-009 | C11: Report | D11: EX Asset Requests Report | E11: reports on | G11: Table | H11: u_ex_asset_request | I11: Reporting | J11: Low | K11: Fictional | L11: Low | O11: EXAMPLE - FICTIONAL. Not part of your environment. Delete when you no longer need it. | P11: =IF(H11="","",IF(H11='Impact Check'!$B$3,COUNTIF($H$3:H11,'Impact Check'!$B$3),"")) -> 4 | Q11: =IF(D11="","",IF(D11='Impact Check'!$B$3,COUNTIF($D$3:D11,'Impact Check'!$B$3),""))
P12: =IF(H12="","",IF(H12='Impact Check'!$B$3,COUNTIF($H$3:H12,'Impact Check'!$B$3),"")) | Q12: =IF(D12="","",IF(D12='Impact Check'!$B$3,COUNTIF($D$3:D12,'Impact Check'!$B$3),""))
P13: =IF(H13="","",IF(H13='Impact Check'!$B$3,COUNTIF($H$3:H13,'Impact Check'!$B$3),"")) | Q13: =IF(D13="","",IF(D13='Impact Check'!$B$3,COUNTIF($D$3:D13,'Impact Check'!$B$3),""))
P14: =IF(H14="","",IF(H14='Impact Check'!$B$3,COUNTIF($H$3:H14,'Impact Check'!$B$3),"")) | Q14: =IF(D14="","",IF(D14='Impact Check'!$B$3,COUNTIF($D$3:D14,'Impact Check'!$B$3),""))
P15: =IF(H15="","",IF(H15='Impact Check'!$B$3,COUNTIF($H$3:H15,'Impact Check'!$B$3),"")) | Q15: =IF(D15="","",IF(D15='Impact Check'!$B$3,COUNTIF($D$3:D15,'Impact Check'!$B$3),""))
P16: =IF(H16="","",IF(H16='Impact Check'!$B$3,COUNTIF($H$3:H16,'Impact Check'!$B$3),"")) | Q16: =IF(D16="","",IF(D16='Impact Check'!$B$3,COUNTIF($D$3:D16,'Impact Check'!$B$3),""))
P17: =IF(H17="","",IF(H17='Impact Check'!$B$3,COUNTIF($H$3:H17,'Impact Check'!$B$3),"")) | Q17: =IF(D17="","",IF(D17='Impact Check'!$B$3,COUNTIF($D$3:D17,'Impact Check'!$B$3),""))
P18: =IF(H18="","",IF(H18='Impact Check'!$B$3,COUNTIF($H$3:H18,'Impact Check'!$B$3),"")) | Q18: =IF(D18="","",IF(D18='Impact Check'!$B$3,COUNTIF($D$3:D18,'Impact Check'!$B$3),""))
P19: =IF(H19="","",IF(H19='Impact Check'!$B$3,COUNTIF($H$3:H19,'Impact Check'!$B$3),"")) | Q19: =IF(D19="","",IF(D19='Impact Check'!$B$3,COUNTIF($D$3:D19,'Impact Check'!$B$3),""))
P20: =IF(H20="","",IF(H20='Impact Check'!$B$3,COUNTIF($H$3:H20,'Impact Check'!$B$3),"")) | Q20: =IF(D20="","",IF(D20='Impact Check'!$B$3,COUNTIF($D$3:D20,'Impact Check'!$B$3),""))
P21: =IF(H21="","",IF(H21='Impact Check'!$B$3,COUNTIF($H$3:H21,'Impact Check'!$B$3),"")) | Q21: =IF(D21="","",IF(D21='Impact Check'!$B$3,COUNTIF($D$3:D21,'Impact Check'!$B$3),""))
P22: =IF(H22="","",IF(H22='Impact Check'!$B$3,COUNTIF($H$3:H22,'Impact Check'!$B$3),"")) | Q22: =IF(D22="","",IF(D22='Impact Check'!$B$3,COUNTIF($D$3:D22,'Impact Check'!$B$3),""))
P23: =IF(H23="","",IF(H23='Impact Check'!$B$3,COUNTIF($H$3:H23,'Impact Check'!$B$3),"")) | Q23: =IF(D23="","",IF(D23='Impact Check'!$B$3,COUNTIF($D$3:D23,'Impact Check'!$B$3),""))
... P502: =IF(H502="","",IF(H502='Impact Check'!$B$3,COUNTIF($H$3:H502,'Impact Check'!$B$3),"")) | Q502: =IF(D502="","",IF(D502='Impact Check'!$B$3,COUNTIF($D$3:D502,'Impact Check'!$B$3),""))

Sheet Impact Check
A1: IMPACT CHECK - 'If I change this, what could break?'
A3: Object name (exact match to Dependencies sheet): | B3: u_ex_asset_request | C3: <- type an object name (example value is fictional). Then repeat for each dependent you find: that is your second-hop impact.
A5: Rows that point AT this object (dependents): | B5: =COUNTIF(Dependencies!$H$3:$H$502,B3) -> 4
A6: Rows this object points TO (it relies on): | B6: =COUNTIF(Dependencies!$D$3:$D$502,B3) -> 0
A7: Confidence warning: | B7: =IF(B5+B6=0,"Nothing recorded. That means 'not documented', NOT 'no dependencies'. Log an Unknown.",IF(COUNTIFS(Dependencies!$H$3:$H$502,B3,Dependencies!$L$3:$L$502,"Low")+COUNTIFS(Dependencies!$D$3:$D$502,B3,Dependencies!$L$3:$L$502,"Low")>0,"Some links are Low confidence - verify before relying on this list.","OK")) -> Some links are Low confidence - verify before relying on this list.
A9: IF I CHANGE THIS, THESE COULD BREAK (dependents)
A10: # | B10: Dependent (source object) | C10: Relationship | D10: Other Object Type | E10: Dependency Type | F10: Criticality | G10: Confidence | H10: Evidence
A11: 1 | B11: =IFERROR(INDEX(Dependencies!$D$3:$D$502,MATCH($A11,Dependencies!$P$3:$P$502,0)),"") -> EX Laptop Request Fulfillment | C11: =IFERROR(INDEX(Dependencies!$E$3:$E$502,MATCH($A11,Dependencies!$P$3:$P$502,0)),"") -> updates | D11: =IFERROR(INDEX(Dependencies!$C$3:$C$502,MATCH($A11,Dependencies!$P$3:$P$502,0)),"") -> Flow | E11: =IFERROR(INDEX(Dependencies!$I$3:$I$502,MATCH($A11,Dependencies!$P$3:$P$502,0)),"") -> Data | F11: =IFERROR(INDEX(Dependencies!$J$3:$J$502,MATCH($A11,Dependencies!$P$3:$P$502,0)),"") -> Critical | G11: =IFERROR(INDEX(Dependencies!$L$3:$L$502,MATCH($A11,Dependencies!$P$3:$P$502,0)),"") -> Medium | H11: =IFERROR(INDEX(Dependencies!$K$3:$K$502,MATCH($A11,Dependencies!$P$3:$P$502,0)),"") -> Fictional
A12: 2 | B12: =IFERROR(INDEX(Dependencies!$D$3:$D$502,MATCH($A12,Dependencies!$P$3:$P$502,0)),"") -> EX Set Cost Center Default | C12: =IFERROR(INDEX(Dependencies!$E$3:$E$502,MATCH($A12,Dependencies!$P$3:$P$502,0)),"") -> runs on | D12: =IFERROR(INDEX(Dependencies!$C$3:$C$502,MATCH($A12,Dependencies!$P$3:$P$502,0)),"") -> Business Rule | E12: =IFERROR(INDEX(Dependencies!$I$3:$I$502,MATCH($A12,Dependencies!$P$3:$P$502,0)),"") -> Code | F12: =IFERROR(INDEX(Dependencies!$J$3:$J$502,MATCH($A12,Dependencies!$P$3:$P$502,0)),"") -> Medium | G12: =IFERROR(INDEX(Dependencies!$L$3:$L$502,MATCH($A12,Dependencies!$P$3:$P$502,0)),"") -> Medium | H12: =IFERROR(INDEX(Dependencies!$K$3:$K$502,MATCH($A12,Dependencies!$P$3:$P$502,0)),"") -> Fictional
A13: 3 | B13: =IFERROR(INDEX(Dependencies!$D$3:$D$502,MATCH($A13,Dependencies!$P$3:$P$502,0)),"") -> EX ACL write u_ex_asset_request | C13: =IFERROR(INDEX(Dependencies!$E$3:$E$502,MATCH($A13,Dependencies!$P$3:$P$502,0)),"") -> protects | D13: =IFERROR(INDEX(Dependencies!$C$3:$C$502,MATCH($A13,Dependencies!$P$3:$P$502,0)),"") -> ACL | E13: =IFERROR(INDEX(Dependencies!$I$3:$I$502,MATCH($A13,Dependencies!$P$3:$P$502,0)),"") -> Security | F13: =IFERROR(INDEX(Dependencies!$J$3:$J$502,MATCH($A13,Dependencies!$P$3:$P$502,0)),"") -> High | G13: =IFERROR(INDEX(Dependencies!$L$3:$L$502,MATCH($A13,Dependencies!$P$3:$P$502,0)),"") -> Medium | H13: =IFERROR(INDEX(Dependencies!$K$3:$K$502,MATCH($A13,Dependencies!$P$3:$P$502,0)),"") -> Fictional
A14: 4 | B14: =IFERROR(INDEX(Dependencies!$D$3:$D$502,MATCH($A14,Dependencies!$P$3:$P$502,0)),"") -> EX Asset Requests Report | C14: =IFERROR(INDEX(Dependencies!$E$3:$E$502,MATCH($A14,Dependencies!$P$3:$P$502,0)),"") -> reports on | D14: =IFERROR(INDEX(Dependencies!$C$3:$C$502,MATCH($A14,Dependencies!$P$3:$P$502,0)),"") -> Report | E14: =IFERROR(INDEX(Dependencies!$I$3:$I$502,MATCH($A14,Dependencies!$P$3:$P$502,0)),"") -> Reporting | F14: =IFERROR(INDEX(Dependencies!$J$3:$J$502,MATCH($A14,Dependencies!$P$3:$P$502,0)),"") -> Low | G14: =IFERROR(INDEX(Dependencies!$L$3:$L$502,MATCH($A14,Dependencies!$P$3:$P$502,0)),"") -> Low | H14: =IFERROR(INDEX(Dependencies!$K$3:$K$502,MATCH($A14,Dependencies!$P$3:$P$502,0)),"") -> Fictional
A15: 5 | B15: =IFERROR(INDEX(Dependencies!$D$3:$D$502,MATCH($A15,Dependencies!$P$3:$P$502,0)),"") | C15: =IFERROR(INDEX(Dependencies!$E$3:$E$502,MATCH($A15,Dependencies!$P$3:$P$502,0)),"") | D15: =IFERROR(INDEX(Dependencies!$C$3:$C$502,MATCH($A15,Dependencies!$P$3:$P$502,0)),"") | E15: =IFERROR(INDEX(Dependencies!$I$3:$I$502,MATCH($A15,Dependencies!$P$3:$P$502,0)),"") | F15: =IFERROR(INDEX(Dependencies!$J$3:$J$502,MATCH($A15,Dependencies!$P$3:$P$502,0)),"") | G15: =IFERROR(INDEX(Dependencies!$L$3:$L$502,MATCH($A15,Dependencies!$P$3:$P$502,0)),"") | H15: =IFERROR(INDEX(Dependencies!$K$3:$K$502,MATCH($A15,Dependencies!$P$3:$P$502,0)),"")
A16: 6 | B16: =IFERROR(INDEX(Dependencies!$D$3:$D$502,MATCH($A16,Dependencies!$P$3:$P$502,0)),"") | C16: =IFERROR(INDEX(Dependencies!$E$3:$E$502,MATCH($A16,Dependencies!$P$3:$P$502,0)),"") | D16: =IFERROR(INDEX(Dependencies!$C$3:$C$502,MATCH($A16,Dependencies!$P$3:$P$502,0)),"") | E16: =IFERROR(INDEX(Dependencies!$I$3:$I$502,MATCH($A16,Dependencies!$P$3:$P$502,0)),"") | F16: =IFERROR(INDEX(Dependencies!$J$3:$J$502,MATCH($A16,Dependencies!$P$3:$P$502,0)),"") | G16: =IFERROR(INDEX(Dependencies!$L$3:$L$502,MATCH($A16,Dependencies!$P$3:$P$502,0)),"") | H16: =IFERROR(INDEX(Dependencies!$K$3:$K$502,MATCH($A16,Dependencies!$P$3:$P$502,0)),"")
A17: 7 | B17: =IFERROR(INDEX(Dependencies!$D$3:$D$502,MATCH($A17,Dependencies!$P$3:$P$502,0)),"") | C17: =IFERROR(INDEX(Dependencies!$E$3:$E$502,MATCH($A17,Dependencies!$P$3:$P$502,0)),"") | D17: =IFERROR(INDEX(Dependencies!$C$3:$C$502,MATCH($A17,Dependencies!$P$3:$P$502,0)),"") | E17: =IFERROR(INDEX(Dependencies!$I$3:$I$502,MATCH($A17,Dependencies!$P$3:$P$502,0)),"") | F17: =IFERROR(INDEX(Dependencies!$J$3:$J$502,MATCH($A17,Dependencies!$P$3:$P$502,0)),"") | G17: =IFERROR(INDEX(Dependencies!$L$3:$L$502,MATCH($A17,Dependencies!$P$3:$P$502,0)),"") | H17: =IFERROR(INDEX(Dependencies!$K$3:$K$502,MATCH($A17,Dependencies!$P$3:$P$502,0)),"")
A18: 8 | B18: =IFERROR(INDEX(Dependencies!$D$3:$D$502,MATCH($A18,Dependencies!$P$3:$P$502,0)),"") | C18: =IFERROR(INDEX(Dependencies!$E$3:$E$502,MATCH($A18,Dependencies!$P$3:$P$502,0)),"") | D18: =IFERROR(INDEX(Dependencies!$C$3:$C$502,MATCH($A18,Dependencies!$P$3:$P$502,0)),"") | E18: =IFERROR(INDEX(Dependencies!$I$3:$I$502,MATCH($A18,Dependencies!$P$3:$P$502,0)),"") | F18: =IFERROR(INDEX(Dependencies!$J$3:$J$502,MATCH($A18,Dependencies!$P$3:$P$502,0)),"") | G18: =IFERROR(INDEX(Dependencies!$L$3:$L$502,MATCH($A18,Dependencies!$P$3:$P$502,0)),"") | H18: =IFERROR(INDEX(Dependencies!$K$3:$K$502,MATCH($A18,Dependencies!$P$3:$P$502,0)),"")
A19: 9 | B19: =IFERROR(INDEX(Dependencies!$D$3:$D$502,MATCH($A19,Dependencies!$P$3:$P$502,0)),"") | C19: =IFERROR(INDEX(Dependencies!$E$3:$E$502,MATCH($A19,Dependencies!$P$3:$P$502,0)),"") | D19: =IFERROR(INDEX(Dependencies!$C$3:$C$502,MATCH($A19,Dependencies!$P$3:$P$502,0)),"") | E19: =IFERROR(INDEX(Dependencies!$I$3:$I$502,MATCH($A19,Dependencies!$P$3:$P$502,0)),"") | F19: =IFERROR(INDEX(Dependencies!$J$3:$J$502,MATCH($A19,Dependencies!$P$3:$P$502,0)),"") | G19: =IFERROR(INDEX(Dependencies!$L$3:$L$502,MATCH($A19,Dependencies!$P$3:$P$502,0)),"") | H19: =IFERROR(INDEX(Dependencies!$K$3:$K$502,MATCH($A19,Dependencies!$P$3:$P$502,0)),"")
A20: 10 | B20: =IFERROR(INDEX(Dependencies!$D$3:$D$502,MATCH($A20,Dependencies!$P$3:$P$502,0)),"") | C20: =IFERROR(INDEX(Dependencies!$E$3:$E$502,MATCH($A20,Dependencies!$P$3:$P$502,0)),"") | D20: =IFERROR(INDEX(Dependencies!$C$3:$C$502,MATCH($A20,Dependencies!$P$3:$P$502,0)),"") | E20: =IFERROR(INDEX(Dependencies!$I$3:$I$502,MATCH($A20,Dependencies!$P$3:$P$502,0)),"") | F20: =IFERROR(INDEX(Dependencies!$J$3:$J$502,MATCH($A20,Dependencies!$P$3:$P$502,0)),"") | G20: =IFERROR(INDEX(Dependencies!$L$3:$L$502,MATCH($A20,Dependencies!$P$3:$P$502,0)),"") | H20: =IFERROR(INDEX(Dependencies!$K$3:$K$502,MATCH($A20,Dependencies!$P$3:$P$502,0)),"")
A21: 11 | B21: =IFERROR(INDEX(Dependencies!$D$3:$D$502,MATCH($A21,Dependencies!$P$3:$P$502,0)),"") | C21: =IFERROR(INDEX(Dependencies!$E$3:$E$502,MATCH($A21,Dependencies!$P$3:$P$502,0)),"") | D21: =IFERROR(INDEX(Dependencies!$C$3:$C$502,MATCH($A21,Dependencies!$P$3:$P$502,0)),"") | E21: =IFERROR(INDEX(Dependencies!$I$3:$I$502,MATCH($A21,Dependencies!$P$3:$P$502,0)),"") | F21: =IFERROR(INDEX(Dependencies!$J$3:$J$502,MATCH($A21,Dependencies!$P$3:$P$502,0)),"") | G21: =IFERROR(INDEX(Dependencies!$L$3:$L$502,MATCH($A21,Dependencies!$P$3:$P$502,0)),"") | H21: =IFERROR(INDEX(Dependencies!$K$3:$K$502,MATCH($A21,Dependencies!$P$3:$P$502,0)),"")
A22: 12 | B22: =IFERROR(INDEX(Dependencies!$D$3:$D$502,MATCH($A22,Dependencies!$P$3:$P$502,0)),"") | C22: =IFERROR(INDEX(Dependencies!$E$3:$E$502,MATCH($A22,Dependencies!$P$3:$P$502,0)),"") | D22: =IFERROR(INDEX(Dependencies!$C$3:$C$502,MATCH($A22,Dependencies!$P$3:$P$502,0)),"") | E22: =IFERROR(INDEX(Dependencies!$I$3:$I$502,MATCH($A22,Dependencies!$P$3:$P$502,0)),"") | F22: =IFERROR(INDEX(Dependencies!$J$3:$J$502,MATCH($A22,Dependencies!$P$3:$P$502,0)),"") | G22: =IFERROR(INDEX(Dependencies!$L$3:$L$502,MATCH($A22,Dependencies!$P$3:$P$502,0)),"") | H22: =IFERROR(INDEX(Dependencies!$K$3:$K$502,MATCH($A22,Dependencies!$P$3:$P$502,0)),"")
... A35: 25 | B35: =IFERROR(INDEX(Dependencies!$D$3:$D$502,MATCH($A35,Dependencies!$P$3:$P$502,0)),"") | C35: =IFERROR(INDEX(Dependencies!$E$3:$E$502,MATCH($A35,Dependencies!$P$3:$P$502,0)),"") | D35: =IFERROR(INDEX(Dependencies!$C$3:$C$502,MATCH($A35,Dependencies!$P$3:$P$502,0)),"") | E35: =IFERROR(INDEX(Dependencies!$I$3:$I$502,MATCH($A35,Dependencies!$P$3:$P$502,0)),"") | F35: =IFERROR(INDEX(Dependencies!$J$3:$J$502,MATCH($A35,Dependencies!$P$3:$P$502,0)),"") | G35: =IFERROR(INDEX(Dependencies!$L$3:$L$502,MATCH($A35,Dependencies!$P$3:$P$502,0)),"") | H35: =IFERROR(INDEX(Dependencies!$K$3:$K$502,MATCH($A35,Dependencies!$P$3:$P$502,0)),"")
A37: THIS OBJECT RELIES ON (its dependencies)
A38: # | B38: Depends On (target object) | C38: Relationship | D38: Other Object Type | E38: Dependency Type | F38: Criticality | G38: Confidence | H38: Evidence
A39: 1 | B39: =IFERROR(INDEX(Dependencies!$H$3:$H$502,MATCH($A39,Dependencies!$Q$3:$Q$502,0)),"") | C39: =IFERROR(INDEX(Dependencies!$E$3:$E$502,MATCH($A39,Dependencies!$Q$3:$Q$502,0)),"") | D39: =IFERROR(INDEX(Dependencies!$G$3:$G$502,MATCH($A39,Dependencies!$Q$3:$Q$502,0)),"") | E39: =IFERROR(INDEX(Dependencies!$I$3:$I$502,MATCH($A39,Dependencies!$Q$3:$Q$502,0)),"") | F39: =IFERROR(INDEX(Dependencies!$J$3:$J$502,MATCH($A39,Dependencies!$Q$3:$Q$502,0)),"") | G39: =IFERROR(INDEX(Dependencies!$L$3:$L$502,MATCH($A39,Dependencies!$Q$3:$Q$502,0)),"") | H39: =IFERROR(INDEX(Dependencies!$K$3:$K$502,MATCH($A39,Dependencies!$Q$3:$Q$502,0)),"")
A40: 2 | B40: =IFERROR(INDEX(Dependencies!$H$3:$H$502,MATCH($A40,Dependencies!$Q$3:$Q$502,0)),"") | C40: =IFERROR(INDEX(Dependencies!$E$3:$E$502,MATCH($A40,Dependencies!$Q$3:$Q$502,0)),"") | D40: =IFERROR(INDEX(Dependencies!$G$3:$G$502,MATCH($A40,Dependencies!$Q$3:$Q$502,0)),"") | E40: =IFERROR(INDEX(Dependencies!$I$3:$I$502,MATCH($A40,Dependencies!$Q$3:$Q$502,0)),"") | F40: =IFERROR(INDEX(Dependencies!$J$3:$J$502,MATCH($A40,Dependencies!$Q$3:$Q$502,0)),"") | G40: =IFERROR(INDEX(Dependencies!$L$3:$L$502,MATCH($A40,Dependencies!$Q$3:$Q$502,0)),"") | H40: =IFERROR(INDEX(Dependencies!$K$3:$K$502,MATCH($A40,Dependencies!$Q$3:$Q$502,0)),"")
A41: 3 | B41: =IFERROR(INDEX(Dependencies!$H$3:$H$502,MATCH($A41,Dependencies!$Q$3:$Q$502,0)),"") | C41: =IFERROR(INDEX(Dependencies!$E$3:$E$502,MATCH($A41,Dependencies!$Q$3:$Q$502,0)),"") | D41: =IFERROR(INDEX(Dependencies!$G$3:$G$502,MATCH($A41,Dependencies!$Q$3:$Q$502,0)),"") | E41: =IFERROR(INDEX(Dependencies!$I$3:$I$502,MATCH($A41,Dependencies!$Q$3:$Q$502,0)),"") | F41: =IFERROR(INDEX(Dependencies!$J$3:$J$502,MATCH($A41,Dependencies!$Q$3:$Q$502,0)),"") | G41: =IFERROR(INDEX(Dependencies!$L$3:$L$502,MATCH($A41,Dependencies!$Q$3:$Q$502,0)),"") | H41: =IFERROR(INDEX(Dependencies!$K$3:$K$502,MATCH($A41,Dependencies!$Q$3:$Q$502,0)),"")
A42: 4 | B42: =IFERROR(INDEX(Dependencies!$H$3:$H$502,MATCH($A42,Dependencies!$Q$3:$Q$502,0)),"") | C42: =IFERROR(INDEX(Dependencies!$E$3:$E$502,MATCH($A42,Dependencies!$Q$3:$Q$502,0)),"") | D42: =IFERROR(INDEX(Dependencies!$G$3:$G$502,MATCH($A42,Dependencies!$Q$3:$Q$502,0)),"") | E42: =IFERROR(INDEX(Dependencies!$I$3:$I$502,MATCH($A42,Dependencies!$Q$3:$Q$502,0)),"") | F42: =IFERROR(INDEX(Dependencies!$J$3:$J$502,MATCH($A42,Dependencies!$Q$3:$Q$502,0)),"") | G42: =IFERROR(INDEX(Dependencies!$L$3:$L$502,MATCH($A42,Dependencies!$Q$3:$Q$502,0)),"") | H42: =IFERROR(INDEX(Dependencies!$K$3:$K$502,MATCH($A42,Dependencies!$Q$3:$Q$502,0)),"")
A43: 5 | B43: =IFERROR(INDEX(Dependencies!$H$3:$H$502,MATCH($A43,Dependencies!$Q$3:$Q$502,0)),"") | C43: =IFERROR(INDEX(Dependencies!$E$3:$E$502,MATCH($A43,Dependencies!$Q$3:$Q$502,0)),"") | D43: =IFERROR(INDEX(Dependencies!$G$3:$G$502,MATCH($A43,Dependencies!$Q$3:$Q$502,0)),"") | E43: =IFERROR(INDEX(Dependencies!$I$3:$I$502,MATCH($A43,Dependencies!$Q$3:$Q$502,0)),"") | F43: =IFERROR(INDEX(Dependencies!$J$3:$J$502,MATCH($A43,Dependencies!$Q$3:$Q$502,0)),"") | G43: =IFERROR(INDEX(Dependencies!$L$3:$L$502,MATCH($A43,Dependencies!$Q$3:$Q$502,0)),"") | H43: =IFERROR(INDEX(Dependencies!$K$3:$K$502,MATCH($A43,Dependencies!$Q$3:$Q$502,0)),"")
A44: 6 | B44: =IFERROR(INDEX(Dependencies!$H$3:$H$502,MATCH($A44,Dependencies!$Q$3:$Q$502,0)),"") | C44: =IFERROR(INDEX(Dependencies!$E$3:$E$502,MATCH($A44,Dependencies!$Q$3:$Q$502,0)),"") | D44: =IFERROR(INDEX(Dependencies!$G$3:$G$502,MATCH($A44,Dependencies!$Q$3:$Q$502,0)),"") | E44: =IFERROR(INDEX(Dependencies!$I$3:$I$502,MATCH($A44,Dependencies!$Q$3:$Q$502,0)),"") | F44: =IFERROR(INDEX(Dependencies!$J$3:$J$502,MATCH($A44,Dependencies!$Q$3:$Q$502,0)),"") | G44: =IFERROR(INDEX(Dependencies!$L$3:$L$502,MATCH($A44,Dependencies!$Q$3:$Q$502,0)),"") | H44: =IFERROR(INDEX(Dependencies!$K$3:$K$502,MATCH($A44,Dependencies!$Q$3:$Q$502,0)),"")
A45: 7 | B45: =IFERROR(INDEX(Dependencies!$H$3:$H$502,MATCH($A45,Dependencies!$Q$3:$Q$502,0)),"") | C45: =IFERROR(INDEX(Dependencies!$E$3:$E$502,MATCH($A45,Dependencies!$Q$3:$Q$502,0)),"") | D45: =IFERROR(INDEX(Dependencies!$G$3:$G$502,MATCH($A45,Dependencies!$Q$3:$Q$502,0)),"") | E45: =IFERROR(INDEX(Dependencies!$I$3:$I$502,MATCH($A45,Dependencies!$Q$3:$Q$502,0)),"") | F45: =IFERROR(INDEX(Dependencies!$J$3:$J$502,MATCH($A45,Dependencies!$Q$3:$Q$502,0)),"") | G45: =IFERROR(INDEX(Dependencies!$L$3:$L$502,MATCH($A45,Dependencies!$Q$3:$Q$502,0)),"") | H45: =IFERROR(INDEX(Dependencies!$K$3:$K$502,MATCH($A45,Dependencies!$Q$3:$Q$502,0)),"")
A46: 8 | B46: =IFERROR(INDEX(Dependencies!$H$3:$H$502,MATCH($A46,Dependencies!$Q$3:$Q$502,0)),"") | C46: =IFERROR(INDEX(Dependencies!$E$3:$E$502,MATCH($A46,Dependencies!$Q$3:$Q$502,0)),"") | D46: =IFERROR(INDEX(Dependencies!$G$3:$G$502,MATCH($A46,Dependencies!$Q$3:$Q$502,0)),"") | E46: =IFERROR(INDEX(Dependencies!$I$3:$I$502,MATCH($A46,Dependencies!$Q$3:$Q$502,0)),"") | F46: =IFERROR(INDEX(Dependencies!$J$3:$J$502,MATCH($A46,Dependencies!$Q$3:$Q$502,0)),"") | G46: =IFERROR(INDEX(Dependencies!$L$3:$L$502,MATCH($A46,Dependencies!$Q$3:$Q$502,0)),"") | H46: =IFERROR(INDEX(Dependencies!$K$3:$K$502,MATCH($A46,Dependencies!$Q$3:$Q$502,0)),"")
A47: 9 | B47: =IFERROR(INDEX(Dependencies!$H$3:$H$502,MATCH($A47,Dependencies!$Q$3:$Q$502,0)),"") | C47: =IFERROR(INDEX(Dependencies!$E$3:$E$502,MATCH($A47,Dependencies!$Q$3:$Q$502,0)),"") | D47: =IFERROR(INDEX(Dependencies!$G$3:$G$502,MATCH($A47,Dependencies!$Q$3:$Q$502,0)),"") | E47: =IFERROR(INDEX(Dependencies!$I$3:$I$502,MATCH($A47,Dependencies!$Q$3:$Q$502,0)),"") | F47: =IFERROR(INDEX(Dependencies!$J$3:$J$502,MATCH($A47,Dependencies!$Q$3:$Q$502,0)),"") | G47: =IFERROR(INDEX(Dependencies!$L$3:$L$502,MATCH($A47,Dependencies!$Q$3:$Q$502,0)),"") | H47: =IFERROR(INDEX(Dependencies!$K$3:$K$502,MATCH($A47,Dependencies!$Q$3:$Q$502,0)),"")
A48: 10 | B48: =IFERROR(INDEX(Dependencies!$H$3:$H$502,MATCH($A48,Dependencies!$Q$3:$Q$502,0)),"") | C48: =IFERROR(INDEX(Dependencies!$E$3:$E$502,MATCH($A48,Dependencies!$Q$3:$Q$502,0)),"") | D48: =IFERROR(INDEX(Dependencies!$G$3:$G$502,MATCH($A48,Dependencies!$Q$3:$Q$502,0)),"") | E48: =IFERROR(INDEX(Dependencies!$I$3:$I$502,MATCH($A48,Dependencies!$Q$3:$Q$502,0)),"") | F48: =IFERROR(INDEX(Dependencies!$J$3:$J$502,MATCH($A48,Dependencies!$Q$3:$Q$502,0)),"") | G48: =IFERROR(INDEX(Dependencies!$L$3:$L$502,MATCH($A48,Dependencies!$Q$3:$Q$502,0)),"") | H48: =IFERROR(INDEX(Dependencies!$K$3:$K$502,MATCH($A48,Dependencies!$Q$3:$Q$502,0)),"")
A49: 11 | B49: =IFERROR(INDEX(Dependencies!$H$3:$H$502,MATCH($A49,Dependencies!$Q$3:$Q$502,0)),"") | C49: =IFERROR(INDEX(Dependencies!$E$3:$E$502,MATCH($A49,Dependencies!$Q$3:$Q$502,0)),"") | D49: =IFERROR(INDEX(Dependencies!$G$3:$G$502,MATCH($A49,Dependencies!$Q$3:$Q$502,0)),"") | E49: =IFERROR(INDEX(Dependencies!$I$3:$I$502,MATCH($A49,Dependencies!$Q$3:$Q$502,0)),"") | F49: =IFERROR(INDEX(Dependencies!$J$3:$J$502,MATCH($A49,Dependencies!$Q$3:$Q$502,0)),"") | G49: =IFERROR(INDEX(Dependencies!$L$3:$L$502,MATCH($A49,Dependencies!$Q$3:$Q$502,0)),"") | H49: =IFERROR(INDEX(Dependencies!$K$3:$K$502,MATCH($A49,Dependencies!$Q$3:$Q$502,0)),"")
A50: 12 | B50: =IFERROR(INDEX(Dependencies!$H$3:$H$502,MATCH($A50,Dependencies!$Q$3:$Q$502,0)),"") | C50: =IFERROR(INDEX(Dependencies!$E$3:$E$502,MATCH($A50,Dependencies!$Q$3:$Q$502,0)),"") | D50: =IFERROR(INDEX(Dependencies!$G$3:$G$502,MATCH($A50,Dependencies!$Q$3:$Q$502,0)),"") | E50: =IFERROR(INDEX(Dependencies!$I$3:$I$502,MATCH($A50,Dependencies!$Q$3:$Q$502,0)),"") | F50: =IFERROR(INDEX(Dependencies!$J$3:$J$502,MATCH($A50,Dependencies!$Q$3:$Q$502,0)),"") | G50: =IFERROR(INDEX(Dependencies!$L$3:$L$502,MATCH($A50,Dependencies!$Q$3:$Q$502,0)),"") | H50: =IFERROR(INDEX(Dependencies!$K$3:$K$502,MATCH($A50,Dependencies!$Q$3:$Q$502,0)),"")
